Workbook

Sheet Read Me
A1: EF Client Hub Codebook
A2: Compiled for | B2: Executive Frame Client Hub (clients.executiveframe.co.nz), from the Charlotte Price Consulting Psychometric Codebook
A3: Compiled | B3: 18 October 2026 (duplicated from the CPC codebook compiled 26 September 2026)
A4: Scope | B4: The working set of 20 instruments selected for practice use, across 6 domains. 307 items are reproduced verbatim.
A5: Sources | B5: NovoPsych assessment pages and blank form PDFs, the official University of New South Wales DASS site, instrument developers, and original validation papers or authoritative open reproductions. Every record carries its source URL.
A7: Domains
A8: 1. Executive functioning and ADHD | B8: ESQ-R, CFI and ASRS. The ESQ-R is the executive skills core of both executive function batteries and the ASRS adds current adult ADHD symptom screening. The CFI measures cognitive flexibility and is now used in the Perfectionism battery rather than the executive function batteries.
A9: 2. Strengths knowledge, use and support at work | B9: SKS, SUS and SSES: whether a client knows their strengths, uses them, and is confident applying them. These are the measures that show change across a coaching engagement.
A10: 3. Adjacent occupational and wellbeing | B10: Core Self Evaluations Scale and Psychological Empowerment Scale: general positive self appraisal and felt empowerment in a work role.
A11: 4. Psychological distress screening | B11: DASS-21: depression, anxiety and stress over the past week. A screening measure used to establish whether coaching can safely proceed and whether clinical input is needed.
A12: 5. Repetitive negative thinking and self talk | B12: PTQ and RRS measure the process of repetitive negative thinking rather than the resulting mood, which the DASS-21 captures. FSCRS and PCI measure self critical and perfectionistic self talk, and the SCS-SF measures the self compassionate counterpart that coaching aims to build.
A13: 6. Motivation, self determination and goal pursuit | B13: Basic Psychological Need Satisfaction and Frustration Scale, Pure and Irrational Procrastination Scales, General Self-Efficacy Scale, Goal Commitment Scale and Goal Adjustment Scale. The last 2 are specific to goals: commitment to a goal the client names, and the capacity to let go of unattainable goals and take up new ones.
A15: Sheet | B15: Contents
A16: Hub Library | B16: One row per instrument as it appears in the Client Hub: the id and client facing name, whether it is included, its licence status for the hub (only cleared instruments can be assigned to clients), whether clients see strengths and areas of focus, item flags for Sarah, and the instructions shown on screen. Edit this sheet, then run npm run codebook to rebuild the hub library files.
A17: Hub Subscales | B17: One row per subscale as the hub scores it: client facing label, scoring direction, method, optional band thresholds (blank means thirds of the response range), the strength and focus wording clients see once released, and the Learning Hub topic each area of focus links to. All wording is draft for Sarah to approve.
A18: Batteries | B18: The 11 assessment forms used in practice, each a combination of instruments: which instruments each contains, total items, the matching report skill, what it assesses and its scoring cautions. Below it, a map showing which batteries use each instrument.
A19: Tally Prompt | B19: The prompt used to convert an existing Tally assessment form to a different battery, with instructions on which codebook fields to paste in and a checklist for testing the finished form.
A20: Instrument Summary | B20: One row per instrument with domain, availability, item counts, construct, respondent, cost and access, coaching application, instructions, response options, scoring, interpretation, cut-offs, norms, psychometrics, developer citation, copyright and source.
... A24: Individual instrument tabs | B24: One tab per instrument with its metadata block above its own item table.
A26: Hub conventions
A27: Licence status | B27: cleared: can be assigned to clients. review: in the library file but not uploadable until the licence is confirmed. permission: written permission needed before use. excluded: left out of the hub. The hub refuses to assign anything that is not cleared.
A28: Scoring direction | B28: difficulty: a higher score means more difficulty, so low scores are strengths and high scores are areas of focus. positive: the reverse. none: scored for Sarah only, never summarised to the client. Reverse scored items are reversed as min plus max minus the answer, so 1 to 7 scales reverse correctly.
A29: Conventions
A30: Verbatim wording | B30: Item text is transcribed word for word from the source named against each instrument. Nothing has been paraphrased or reconstructed. Where an item could not be retrieved the cell says so.
A31: Not stated on source | B31: The field is not published in the sources consulted.
A32: Reverse and filler | B32: TRUE in the reverse column means the item is reversed before summing. TRUE in the filler column means the item is not scored at all.
A33: Spelling | B33: Item wording is reproduced exactly as published, including United States spelling. Surrounding commentary uses UK spelling.
A35: Cautions and known gaps
B36: ESQ-R and CFI are scored in opposite directions: higher ESQ-R means more executive difficulty, higher CFI means more flexibility. The ESQ-R norms are 327 Malaysian working adults; the CFI norms are 196 university students.
B37: ASRS Part A of 14 or more is a positive screen, not a diagnosis. Gallup style caution applies: always pair with clinical interview, and with the WURS-25 where childhood history is needed.
B38: SKS and SUS items are taken from an open access peer reviewed reproduction (Frontiers in Psychology, 2023). CAPP asserts copyright over the scales and one later reuse redacted them, so they are viewable and freely reprinted rather than formally public domain.
B39: DASS-21 is a screening measure only. It describes the past week, contains no item on suicidal thinking and does not assess risk. Items 10, 17 and 21 are followed up directly when endorsed at 2 or 3, as the practice report builder does. Severity labels are population position descriptors, not diagnostic thresholds.
B40: No normative percentile tables exist for the SKS, SUS, SSES, CSES or PES. They are continuous measures best read against a client’s own baseline across repeated administration.
B41: RRS: only the 5 item Brooding and 5 item Reflection subscales are recommended for coaching use. The remaining 12 items overlap with depressive symptom content and are retained for completeness only. NovoPsych hosts the RRS, but its scoring and norm text could not be retrieved, so interpretation here rests on Treynor, Gonzalez and Nolen-Hoeksema (2003).
B42: FSCRS item 9 sits close to self harm content. Frame it with care, and treat endorsement as a prompt for a conversation rather than a score. The FSCRS carries an author copyright notice with no commercial grant or restriction stated; a short email to the authors settles its use in paid practice.
B43: SCS-SF: items 1, 4, 8, 9, 11 and 12 are reverse scored. Higher total scores mean greater self compassion, so the direction runs opposite to the FSCRS, PCI, PTQ and RRS, where higher means more difficulty.
B44: IPS items 2, 6 and 9 are reverse scored. The PPS has no reversed items. Both are free for research and clinical purposes per the author, with items from a CC BY article.
B45: GCS: the 5 items refer to a goal the client names, so the form must ask for that goal first; no verbatim published instructions were located. Items 1, 2 and 4 are reverse scored. Commercial use may need permission from Howard Klein. The items were corrected against Klein et al. (2001) after an aggregator site listed 2 items from the older 9 item scale.
B46: GADJ (Goal Adjustment Scale, coded GADJ to avoid confusion with Goal Attainment Scaling): 4 disengagement and 6 reengagement items, scored separately; items 2 and 3 are reverse scored. The published article carries no licence statement, and permission should be sought from Carsten Wrosch before paid use.
B47: BPNSFS: copyrighted by the Center for Self-Determination Theory. Academic use is free, but the Center’s terms state it may not be used for any commercial purpose without written permission, and paid coaching counts as commercial. Request a commercial licence through the Center before using it with clients. The 6 subscales of 4 items each are scored separately; satisfaction and frustration are distinct constructs with different links to wellbeing and ill being, so read them as a profile rather than combining them. No items are reverse scored. Reliability figures come from an open academia.edu copy of Chen et al. (2015) and should be checked against the journal version before quoting. It replaces the older 21 item Basic Psychological Need Satisfaction in General Scale, which fitted poorly.

Sheet Hub Library
A1: Code | B1: Hub id | C1: Name shown to clients | D1: Full instrument name | E1: Include in hub (Yes / No / Decide) | F1: Hub licence status (cleared / review / permission / excluded) | G1: Licence note | H1: Client sees strengths and focus (Yes / No) | I1: Flag items for Sarah (item numbers at threshold) | J1: Instructions shown to the client | K1: Minutes | L1: Notes
A2: ESQ-R | B2: esq-r | C2: Everyday executive skills | D2: Executive Skills Questionnaire - Revised (ESQ-R) | E2: Yes | F2: review | G2: Strait et al. (2020) scale, free to use; NovoPsych page carries a NovoPsych copyright notice. Confirm with Dr Peg Dawson or the authors before clearing. | H2: Yes | J2: Read each item and decide how often it's a problem for you. | K2: 5
A3: CFI | B3: cfi | C3: Thinking flexibly | D3: Cognitive Flexibility Inventory (CFI) | E3: Yes | F3: review | G3: Dennis and Vander Wal (2010); NovoPsych reproduction carries a NovoPsych copyright notice. Confirm author permission before clearing. | H3: Yes | J3: Please use the scale below to indicate the extent to which you agree or disagree with the following statements. | K3: 4
A4: ASRS | B4: asrs | C4: Attention and activity | D4: Adult ADHD Self-Report Scale (ASRS v1.1) | E4: Yes | F4: cleared | G4: Public domain WHO instrument, freely reproducible for clinical use. | H4: No | J4: Please answer the questions below, rating yourself on each of the criteria shown. As you answer each question, select the box that best describes how you have felt and conducted yourself over the past 6 months. | K4: 4
A5: SKS | B5: sks | C5: Knowing your strengths | D5: Strengths Knowledge Scale | E5: Yes | F5: review | G5: No explicit licence found; CAPP asserts copyright over the scales. Confirm before clearing. | H5: Yes | J5: Not stated on source | K5: 2
A6: SUS | B6: sus | C6: Using your strengths | D6: Strengths Use Scale | E6: Yes | F6: review | G6: No explicit licence found; CAPP asserts copyright over the scales. Confirm before clearing. | H6: Yes | J6: The following 14 questions ask about your strengths, that is, the things that you can do well or do best. | K6: 3
A7: SSES | B7: sses | C7: Confidence in your strengths | D7: Strengths Self-Efficacy Scale | E7: Yes | F7: review | G7: Distributed free for practitioner use by PositivePsychology.com; no explicit licence from the authors. Confirm before clearing. | H7: Yes | J7: First, please list your 5 signature strengths below: [space for 5 strengths]. How confident are you in your ability to .... | K7: 3
A8: CSES | B8: cses | C8: How you see yourself | D8: Core Self-Evaluations Scale | E8: Yes | F8: cleared | G8: Stated non proprietary and free to use without permission. | H8: Yes | J8: Not retrieved verbatim from a fetched source; the CSES PDF reproduces the item table and response scale but the source fetched did not include a printed respondent-facing preamble/instruction sentence. | K8: 3
A9: PES | B9: pes | C9: Feeling empowered at work | D9: Psychological Empowerment Scale | E9: Yes | F9: cleared | G9: Hosted freely by the author for research and practice use. | H9: Yes | J9: Listed below are a number of self-orientations that people may have with regard to their work role. Using the following scale, please indicate the extent to which you agree or disagree that each one describes your self-orientation. | K9: 3
A10: DASS-21 | B10: dass-21 | C10: How you have been feeling this week | D10: Depression Anxiety Stress Scales, 21 item version (DASS-21) | E10: Yes | F10: cleared | G10: Public domain per the official UNSW DASS site. | H10: No | I10: 10,17,21 at 2 | J10: Please read each statement and choose the answer that shows how much the statement applied to you over the past week. There are no right or wrong answers. Do not spend too much time on any statement. | K10: 4 | L10: Instructions reworded for the screen ("choose the answer" in place of "circle a number"); otherwise verbatim.
A11: PTQ | B11: ptq | C11: Repetitive thinking | D11: Perseverative Thinking Questionnaire | E11: Yes | F11: review | G11: Elsevier copyright on the article; no permission statement for practice use found. Confirm before clearing. | H11: Yes | J11: In this questionnaire, you will be asked to describe how you typically think about negative experiences or problems. Please read the following statements and rate the extent to which they apply to you when you think about negative experiences or problems. | K11: 4
A12: RRS | B12: rrs | C12: Responding to low mood | D12: Ruminative Responses Scale | E12: Yes | F12: review | G12: No explicit licence statement found. Confirm before clearing. Only Brooding and Reflection are scored. | H12: Yes | J12: Please read each of the items below and indicate whether you almost never, sometimes, often, or almost always think or do each one when you feel down, sad, or depressed. Please indicate what you generally do, not what you think you should do. | K12: 5
A13: FSCRS | B13: fscrs | C13: How you talk to yourself | D13: Forms of Self-Criticising/Attacking and Self-Reassuring Scale | E13: Yes | F13: review | G13: Author copyright notice (Gilbert et al., 2004); no explicit practice use grant found. Confirm before clearing. | H13: Yes | I13: 9 at 1 | J13: When things go wrong in our lives or don't work out as we hoped, and we feel we could have done better, we sometimes have negative and self-critical thoughts and feelings. These may take the form of feeling worthless, useless or inferior etc. However, people can also try to be supportive of themselves. Below are a series of thoughts and feelings that people sometimes have. Read each statement carefully and choose the answer that best describes how much each statement is true for you. | K13: 5 | L13: Instructions reworded for the screen ("choose the answer"); otherwise verbatim.
A14: PCI | B14: pci | C14: Perfectionistic thoughts | D14: Perfectionism Cognitions Inventory | E14: Yes | F14: review | G14: No explicit restriction found; Hewitt Lab hosts the document. Confirm before clearing. | H14: Yes | J14: Listed below are a variety of thoughts about perfectionism that sometimes pop into people's heads. Please read each thought and indicate how frequently, if at all, the thoughts occurred to you over the last week. | K14: 5
A15: SCS-SF | B15: scs-sf | C15: Self compassion | D15: Self-Compassion Scale – Short Form | E15: Yes | F15: review | G15: Author permits research use; practice use not addressed. Confirm with Dr Kristin Neff before clearing. | H15: Yes | J15: Please read each statement carefully before answering. Indicate how often you behave in the stated manner. | K15: 3
A16: BPNSFS | B16: bpnsfs | C16: What you need to feel at your best | D16: Basic Psychological Need Satisfaction and Frustration Scale (BPNSFS) | E16: Decide | F16: permission | G16: Copyright Center for Self-Determination Theory; written permission required for commercial use. | H16: Yes | J16: Below, we ask you about the kind of experiences you actually have in your life. Please read each of the following items carefully. You can choose from 1 to 5 to indicate the degree to which the statement is true for you at this point in your life. | K16: 5
A17: PPS | B17: pps | C17: Putting things off | D17: Pure Procrastination Scale | E17: Yes | F17: cleared | G17: Items published under CC BY (Svartdal and Steel, 2017). | H17: Yes | J17: Not stated on source | K17: 3
A18: IPS | B18: ips | C18: Delaying despite good intentions | D18: Irrational Procrastination Scale | E18: Yes | F18: cleared | G18: Items published under CC BY (Svartdal and Steel, 2017). | H18: Yes | J18: Not stated on source | K18: 2
A19: GSE | B19: gse | C19: Confidence in handling challenges | D19: General Self-Efficacy Scale | E19: Yes | F19: cleared | G19: Authors grant permission to use and reproduce. | H19: Yes | J19: Not stated on source | K19: 2
A20: GCS | B20: gcs | C20: Commitment to your goal | D20: Goal Commitment Scale (5-item unidimensional version) | E20: Decide | F20: permission | G20: No licence statement found; paywalled Elsevier article. Confirm before clearing. The form must ask the client to name a goal first. | H20: Yes | J20: Think of the main goal you are working on with Sarah. Answer each statement about that goal. | K20: 2 | L20: No verbatim published instructions exist. Draft wording for Sarah; the hub does not yet ask the client to type the goal.
A21: GADJ | B21: gadj | C21: Adjusting your goals | D21: Goal Adjustment Scale | E21: Decide | F21: permission | G21: Society for Personality and Social Psychology copyright; no permission statement found. Confirm before clearing. | H21: Yes | J21: "If I have to stop pursuing an important goal in my life . . ." This is the generic item stem used for all 10 items in Study 2 and Study 3, quoted verbatim from a footnote to Table 1 of Wrosch et al. (2003), fetched and confirmed in this session. In Study 1, the goal disengagement items only were instead presented against three separate situational stems, one of which is quoted verbatim in the article as: "If it becomes likely that I have to stop pursuing an important goal because I no longer have the opportunity to realize it . . ." | K21: 3

Sheet Hub Subscales
A1: Code | B1: Codebook subscale | C1: Hub subscale id | D1: Label shown to clients | E1: Scoring direction (difficulty / positive / none) | F1: Method (mean / sum) | G1: Lower band up to (blank = third of range) | H1: Upper band up to (blank = two thirds of range) | I1: Strength wording (client sees) | J1: Focus wording (client sees) | K1: Learning Hub topic | L1: Topic URL | M1: Notes
A2: ESQ-R | B2: Plan Management | C2: plan | D2: Planning and managing tasks | E2: difficulty | F2: mean | I2: You described planning and managing tasks as something that mostly goes smoothly for you. | J2: Planning and keeping track of tasks came up often in your answers. | K2: Planning and prioritising | L2: https://app.executiveframe.co.nz/hub/planning
A3: ESQ-R | B3: Time Management | C3: time | D3: Managing time | E3: difficulty | F3: mean | I3: You told us that keeping to time mostly works for you. | J3: Estimating and keeping to time came up as a difficulty in your answers. | K3: Time and estimating | L3: https://app.executiveframe.co.nz/hub/time
A4: ESQ-R | B4: Organization | C4: organisation | D4: Staying organised | E4: difficulty | F4: mean | I4: Keeping things and spaces in order mostly works for you. | J4: Keeping things and spaces in order came up as a difficulty in your answers. | K4: Organising your things and spaces | L4: https://app.executiveframe.co.nz/hub/organisation
A5: ESQ-R | B5: Emotional Regulation | C5: emotion | D5: Managing feelings | E5: difficulty | F5: mean | I5: You described managing strong feelings as something you handle well. | J5: Managing strong feelings came up as a difficulty in your answers. | K5: Managing feelings | L5: https://app.executiveframe.co.nz/hub/emotional-regulation
A6: ESQ-R | B6: Behavioral Regulation | C6: behaviour | D6: Pausing before acting | E6: difficulty | F6: mean | I6: Pausing before acting and sticking with a plan mostly works for you. | J6: Pausing before acting and sticking with a plan came up as a difficulty in your answers. | K6: Pausing and following through | L6: https://app.executiveframe.co.nz/hub/impulse-control
A7: CFI | B7: Alternatives | C7: alternatives | D7: Seeing other options | E7: positive | F7: mean | I7: You described finding other ways of seeing a situation as something that comes readily to you. | J7: Your answers suggest it can be hard to see other ways of reading a situation. | K7: Thinking flexibly | L7: https://app.executiveframe.co.nz/hub/flexible-thinking
A8: CFI | B8: Control | C8: control | D8: Seeing situations as workable | E8: positive | F8: mean | I8: You tend to see difficult situations as ones you can do something about. | J8: Your answers suggest difficult situations can feel outside your control. | K8: Thinking flexibly | L8: https://app.executiveframe.co.nz/hub/flexible-thinking
A9: ASRS | B9: Part A (Criterion / Screener) | C9: part-a | D9: Part A | E9: none | F9: sum | M9: Screener. Scored for Sarah only; the hub never shows this to the client.
A10: ASRS | B10: Part B (Additional Symptoms) | C10: part-b | D10: Part B | E10: none | F10: sum | M10: Scored for Sarah only.
A11: ASRS | B11: Inattentiveness | C11: inattention | D11: Inattention | E11: none | F11: sum | M11: Raw sum; the dichotomous symptom count is read from the shaded boxes by Sarah.
A12: ASRS | B12: Hyperactivity/Impulsivity - Motor | C12: motor | D12: Motor | E12: none | F12: sum | M12: Raw sum.
A13: ASRS | B13: Hyperactivity/Impulsivity - Verbal | C13: verbal | D13: Verbal | E13: none | F13: sum | M13: Raw sum.
A14: SKS | B14: Strengths Knowledge (total scale) | C14: total | D14: Knowing your strengths | E14: positive | F14: mean | I14: You have a clear sense of what your strengths are. | J14: Your answers suggest you are not yet sure what your strengths are, which is a good place to start. | K14: Finding your strengths | L14: https://app.executiveframe.co.nz/hub/strengths
A15: SUS | B15: Strengths Use (total scale) | C15: total | D15: Using your strengths | E15: positive | F15: mean | I15: You described using your strengths often, at work and beyond. | J15: Your answers suggest your strengths do not get much use day to day. | K15: Using your strengths | L15: https://app.executiveframe.co.nz/hub/strengths-use
A16: SSES | B16: Strengths Self-Efficacy (total scale) | C16: total | D16: Confidence in your strengths | E16: positive | F16: mean | I16: You feel confident applying your strengths when it counts. | J16: Your answers suggest you are not yet confident putting your strengths to use. | K16: Using your strengths | L16: https://app.executiveframe.co.nz/hub/strengths-use
A17: CSES | B17: Core Self-Evaluations (total scale, unidimensional) | C17: total | D17: How you see yourself | E17: positive | F17: mean | I17: You described a steady, positive view of yourself and what you can do. | J17: Your answers suggest your view of yourself can be harsh or uncertain. | K17: How you see yourself | L17: https://app.executiveframe.co.nz/hub/self-view
A18: PES | B18: Meaning | C18: meaning | D18: Meaning in your work | E18: positive | F18: mean | I18: Your work feels meaningful to you. | J18: Your answers suggest your work does not feel very meaningful at the moment. | K18: Meaning at work | L18: https://app.executiveframe.co.nz/hub/meaning
A19: PES | B19: Competence | C19: competence | D19: Confidence in your work | E19: positive | F19: mean | I19: You feel capable in your work. | J19: Your answers suggest you are not feeling confident in your work right now. | K19: Confidence at work | L19: https://app.executiveframe.co.nz/hub/competence
A20: PES | B20: Self-Determination | C20: autonomy | D20: Choice in how you work | E20: positive | F20: mean | I20: You have a good deal of say in how you do your work. | J20: Your answers suggest you have little say in how you do your work. | K20: Choice and autonomy at work | L20: https://app.executiveframe.co.nz/hub/autonomy
A21: PES | B21: Impact | C21: impact | D21: Influence at work | E21: positive | F21: mean | I21: You feel your work makes a difference where you are. | J21: Your answers suggest you feel your work has little influence on what happens around you. | K21: Influence at work | L21: https://app.executiveframe.co.nz/hub/impact
A22: DASS-21 | B22: Depression | C22: depression | D22: Depression | E22: difficulty | F22: sum | H22: 4 | M22: Raw sum of 7 items. Doubled score: normal 0 to 9. Sarah only.
A23: DASS-21 | B23: Anxiety | C23: anxiety | D23: Anxiety | E23: difficulty | F23: sum | H23: 3 | M23: Raw sum. Doubled score: normal 0 to 7. Sarah only.
A24: DASS-21 | B24: Stress | C24: stress | D24: Stress | E24: difficulty | F24: sum | H24: 7 | M24: Raw sum. Doubled score: normal 0 to 14. Sarah only.
A25: PTQ | B25: Core Characteristics of Repetitive Negative Thinking | C25: core | D25: Thoughts that go round | E25: difficulty | F25: mean | I25: Thoughts that repeat do not seem to take hold for long with you. | J25: Thoughts that go round and are hard to stop came up often in your answers. | K25: Repetitive thinking | L25: https://app.executiveframe.co.nz/hub/repetitive-thinking
A26: PTQ | B26: Unproductiveness | C26: unproductive | D26: Thinking that goes nowhere | E26: difficulty | F26: mean | I26: When you think things over, it tends to get you somewhere. | J26: Your answers suggest a lot of thinking that does not lead anywhere useful. | K26: Repetitive thinking | L26: https://app.executiveframe.co.nz/hub/repetitive-thinking
A27: PTQ | B27: Capturing Mental Capacity | C27: capacity | D27: Thinking that takes over | E27: difficulty | F27: mean | I27: Your thinking leaves you room for other things. | J27: Your answers suggest repetitive thinking takes up a lot of your mental space. | K27: Repetitive thinking | L27: https://app.executiveframe.co.nz/hub/repetitive-thinking
A28: RRS | B28: Brooding | C28: brooding | D28: Dwelling on what is wrong | E28: difficulty | F28: mean | I28: You do not tend to get stuck dwelling on what is wrong. | J28: Dwelling on what is wrong came up often in your answers. | K28: Getting unstuck from low mood | L28: https://app.executiveframe.co.nz/hub/brooding
A29: RRS | B29: Reflection | C29: reflection | D29: Reflecting on low mood | E29: none | F29: mean | M29: Reflection can be helpful or unhelpful; numbers only.
A30: RRS | B30: Depression-related items (not scored as a subscale) | C30: depressive | D30: Depression related items | E30: none | F30: mean | M30: Not recommended for coaching use; numbers only.
A31: FSCRS | B31: Inadequate Self | C31: inadequate | D31: Feeling not good enough | E31: difficulty | F31: mean | I31: You do not tend to come down hard on yourself when things go wrong. | J31: Feeling not good enough when things go wrong came up often in your answers. | K31: Self criticism | L31: https://app.executiveframe.co.nz/hub/self-criticism
A32: FSCRS | B32: Hated Self | C32: hated | D32: Harsh self attack | E32: difficulty | F32: mean | J32: Your answers include some very harsh thoughts about yourself, which Sarah will talk through with you. | K32: Self criticism | L32: https://app.executiveframe.co.nz/hub/self-criticism | M32: No strength wording; focus wording is deliberately gentle.
A33: FSCRS | B33: Reassured Self | C33: reassured | D33: Reassuring yourself | E33: positive | F33: mean | I33: You are able to be kind and reassuring to yourself when things go wrong. | J33: Your answers suggest reassuring yourself when things go wrong does not come easily yet. | K33: Self compassion | L33: https://app.executiveframe.co.nz/hub/self-compassion
A34: PCI | B34: Perfectionism Cognitions (total scale) | C34: total | D34: Perfectionistic thoughts | E34: difficulty | F34: mean | I34: Thoughts about needing to be perfect do not seem to feature much for you. | J34: Thoughts about needing to be perfect came up often in your answers. | K34: Perfectionism | L34: https://app.executiveframe.co.nz/hub/perfectionism
A35: SCS-SF | B35: Self-Kindness | C35: kindness | D35: Being kind to yourself | E35: positive | F35: mean | I35: You tend to treat yourself with kindness. | J35: Your answers suggest being kind to yourself does not come easily. | K35: Self compassion | L35: https://app.executiveframe.co.nz/hub/self-compassion
A36: SCS-SF | B36: Self-Judgment | C36: judgment | D36: Easing self judgement | E36: positive | F36: mean | I36: You tend not to judge yourself harshly. | J36: Your answers suggest you judge yourself harshly. | K36: Self compassion | L36: https://app.executiveframe.co.nz/hub/self-compassion | M36: Reverse scored, so higher is better.
A37: SCS-SF | B37: Common Humanity | C37: humanity | D37: Feeling you are not alone | E37: positive | F37: mean | I37: You see your struggles as part of being human. | J37: Your answers suggest your struggles feel like yours alone. | K37: Self compassion | L37: https://app.executiveframe.co.nz/hub/self-compassion
A38: SCS-SF | B38: Isolation | C38: isolation | D38: Feeling less isolated | E38: positive | F38: mean | I38: You tend not to feel cut off from others when things are hard. | J38: Your answers suggest you feel cut off from others when things are hard. | K38: Self compassion | L38: https://app.executiveframe.co.nz/hub/self-compassion | M38: Reverse scored, so higher is better.
A39: SCS-SF | B39: Mindfulness | C39: mindfulness | D39: Keeping perspective | E39: positive | F39: mean | I39: You tend to keep feelings in perspective. | J39: Your answers suggest difficult feelings can crowd out perspective. | K39: Self compassion | L39: https://app.executiveframe.co.nz/hub/self-compassion
A40: SCS-SF | B40: Over-Identification | C40: overidentification | D40: Not getting swept up | E40: positive | F40: mean | I40: You tend not to get swept up in difficult feelings. | J40: Your answers suggest difficult feelings can sweep you up. | K40: Self compassion | L40: https://app.executiveframe.co.nz/hub/self-compassion | M40: Reverse scored, so higher is better.
...

Sheet Batteries
A1: Battery (form name) | B1: Notion tag | C1: Instrument codes | D1: Instruments | E1: Items in battery | F1: Administration time by instrument | G1: Report skill | H1: What it assesses | I1: Scoring and interpretation notes
A2: Executive Function Measures | B2: Executive Function (NT) | C2: ESQ-R | D2: Executive Skills Questionnaire - Revised (ESQ-R) | E2: =COUNTIF('Master Item List'!$A:$A,"ESQ-R") | F2: ESQ-R: 5 minutes | G2: ef-measures-report-nt | H2: Executive skills profile for clients without an ADHD diagnosis, locating difficulty across plan management, time management, organisation, emotional regulation and behavioural regulation. | I2: Single instrument battery. Higher ESQ-R scores mean more difficulty. The CFI was removed from this battery on 26 September 2026; check the report skill no longer expects it.
A3: Executive Function Measures (ADHD) | B3: Executive Function (ADHD) | C3: ASRS, ESQ-R | D3: Adult ADHD Self-Report Scale (ASRS v1.1) Executive Skills Questionnaire - Revised (ESQ-R) | E3: =COUNTIF('Master Item List'!$A:$A,"ASRS")+COUNTIF('Master Item List'!$A:$A,"ESQ-R") | F3: ASRS: 3 minutes ESQ-R: 5 minutes | G3: ef-measures-report-adhd | H3: The executive skills profile with current adult ADHD symptom screening added. Use for clients with a diagnosis or where ADHD is a live question. | I3: ASRS Part A of 14 or more is a positive screen, not a diagnosis. The CFI was removed from this battery on 26 September 2026. The report skill description still names the CFI and the ACOS-Self, neither of which is in this battery now; check the skill matches the form.
A4: Strengths Assessment | B4: Strengths | C4: SKS, SUS, SSES | D4: Strengths Knowledge Scale Strengths Use Scale Strengths Self-Efficacy Scale | E4: =COUNTIF('Master Item List'!$A:$A,"SKS")+COUNTIF('Master Item List'!$A:$A,"SUS")+COUNTIF('Master Item List'!$A:$A,"SSES") | F4: SKS: 2-3 minutes SUS: 3-5 minutes SSES: 3-5 minutes | G4: strengths-report | H4: Whether a client knows their strengths, uses them, and feels confident applying them. Suited to repeat administration to show change across a coaching engagement. | I4: No population norms; read against the client’s own baseline.
A5: Work Mindset Assessment | B5: Work Mindset | C5: CSES, PES | D5: Core Self-Evaluations Scale Psychological Empowerment Scale | E5: =COUNTIF('Master Item List'!$A:$A,"CSES")+COUNTIF('Master Item List'!$A:$A,"PES") | F5: CSES: 2-3 minutes PES: 3-5 minutes | G5: work-mindset-report | H5: General positive self appraisal alongside felt empowerment in a work or study role. | I5: The PES assumes a defined work role, so it suits employed and placement clients better than full time students.
A6: DASS-21 | B6: Single Measure | C6: DASS-21 | D6: Depression Anxiety Stress Scales, 21 item version (DASS-21) | E6: =COUNTIF('Master Item List'!$A:$A,"DASS-21") | F6: DASS-21: 4 minutes | G6: dass21-report | H6: Distress screening over the past week, to establish whether coaching can safely proceed and whether clinical input is needed. | I6: Screening only. Contains no suicide item and does not assess risk; items 10, 17 and 21 are followed up directly when endorsed at 2 or 3.
A7: Thinking Patterns | B7: Thinking Patterns | C7: PTQ, RRS | D7: Perseverative Thinking Questionnaire Ruminative Responses Scale | E7: =COUNTIF('Master Item List'!$A:$A,"PTQ")+COUNTIF('Master Item List'!$A:$A,"RRS") | F7: PTQ: Not stated in the source. A brief 15-item self-report measure, typically completed in a few minutes. RRS: Approximately 2 minutes (per NovoPsych). | G7: thinking-patterns-report | H7: The process of repetitive negative thinking rather than the resulting mood: overall perseverative thinking, and brooding versus reflective rumination. | I7: Only the RRS Brooding and Reflection subscales are recommended for coaching interpretation.
A8: Perfectionism | B8: Perfectionism | C8: CFI, PCI | D8: Cognitive Flexibility Inventory (CFI) Perfectionism Cognitions Inventory | E8: =COUNTIF('Master Item List'!$A:$A,"CFI")+COUNTIF('Master Item List'!$A:$A,"PCI") | F8: CFI: 3 minutes PCI: Approximately 4 minutes (per NovoPsych). | G8: perfectionism-report | H8: Frequency of perfectionistic self talk, paired with cognitive flexibility as the capacity that loosens it. | I8: PCI higher means more perfectionistic thinking; CFI higher means more flexibility.
A9: Self-Appraisal Assessment | B9: Self-Appraisal | C9: FSCRS, SCS-SF | D9: Forms of Self-Criticising/Attacking and Self-Reassuring Scale Self-Compassion Scale – Short Form | E9: =COUNTIF('Master Item List'!$A:$A,"FSCRS")+COUNTIF('Master Item List'!$A:$A,"SCS-SF") | F9: FSCRS: Not stated in the source. A brief 22-item self-report measure, typically completed in a few minutes. SCS-SF: Approximately 2 minutes (per NovoPsych). | G9: self-appraisal-report | H9: How a client talks to themselves when things go wrong: self critical and self reassuring forms from the FSCRS, and self compassion from the SCS-SF. | I9: FSCRS item 9 sits close to self harm content; frame with care. SCS-SF higher means more self compassion, the opposite direction to the FSCRS Inadequate and Hated Self subscales.
A10: Procrastination | B10: Procrastination | C10: PPS, IPS | D10: Pure Procrastination Scale Irrational Procrastination Scale | E10: =COUNTIF('Master Item List'!$A:$A,"PPS")+COUNTIF('Master Item List'!$A:$A,"IPS") | F10: PPS: 2-3 minutes IPS: 1-2 minutes | G10: procrastination-report | H10: General delay across decisions and tasks (PPS) and delay that the client recognises as harmful to them (IPS). | I10: IPS items 2, 6 and 9 are reverse scored.
A11: Goal Pursuit | B11: Goal Pursuit | C11: GSE, GCS, GADJ | D11: General Self-Efficacy Scale Goal Commitment Scale (5-item unidimensional version) Goal Adjustment Scale | E11: =COUNTIF('Master Item List'!$A:$A,"GSE")+COUNTIF('Master Item List'!$A:$A,"GCS")+COUNTIF('Master Item List'!$A:$A,"GADJ") | F11: GSE: 4 minutes average (per the official FU Berlin documentation) GCS: Not stated on source GADJ: Not stated on source | G11: No report skill yet | H11: General confidence in managing difficulty (GSE), commitment to a specific goal the client names (GCS), and the capacity to let go of unattainable goals and take up new ones (GADJ). | I11: GCS items refer to a goal the client names, so the form must ask for the goal first; GCS items 1, 2 and 4 are reverse scored. Score the 2 GADJ subscales separately; GADJ items 2 and 3 are reverse scored. Both the GCS and GADJ need author permission for paid use.
A12: Self-Determination | B12: Self Determination | C12: BPNSFS | D12: Basic Psychological Need Satisfaction and Frustration Scale (BPNSFS) | E12: =COUNTIF('Master Item List'!$A:$A,"BPNSFS") | F12: BPNSFS: Not stated on source | G12: self-determination-report | H12: Satisfaction and frustration of the needs for autonomy, competence and relatedness, to locate whether low motivation reflects unmet needs or actively thwarted ones. | I12: Keep the 6 subscales separate. Commercial use needs written permission from the Center for Self-Determination Theory.
A14: Instrument to battery map
A15: Instrument code | B15: Instrument | C15: Batteries using it
A16: ESQ-R | B16: Executive Skills Questionnaire - Revised (ESQ-R) | C16: Executive Function Measures Executive Function Measures (ADHD)
A17: CFI | B17: Cognitive Flexibility Inventory (CFI) | C17: Perfectionism
A18: ASRS | B18: Adult ADHD Self-Report Scale (ASRS v1.1) | C18: Executive Function Measures (ADHD)
A19: SKS | B19: Strengths Knowledge Scale | C19: Strengths Assessment
A20: SUS | B20: Strengths Use Scale | C20: Strengths Assessment
A21: SSES | B21: Strengths Self-Efficacy Scale | C21: Strengths Assessment
A22: CSES | B22: Core Self-Evaluations Scale | C22: Work Mindset Assessment
A23: PES | B23: Psychological Empowerment Scale | C23: Work Mindset Assessment
A24: DASS-21 | B24: Depression Anxiety Stress Scales, 21 item version (DASS-21) | C24: DASS-21
A25: PTQ | B25: Perseverative Thinking Questionnaire | C25: Thinking Patterns
A26: RRS | B26: Ruminative Responses Scale | C26: Thinking Patterns
... A35: GADJ | B35: Goal Adjustment Scale | C35: Goal Pursuit

Sheet Tally Prompt
A1: Tally form conversion prompt
A2: Use this prompt in Tally when converting an existing assessment form to a different battery. Copy the prompt from the single cell in row 5 (select the cell, copy, paste into Tally), then replace the final placeholder with the rows for each instrument in the battery. The Batteries tab lists which instruments belong to each form. For each instrument, paste from the Instrument Summary: Instrument Name and Code, Instructions / prompt, Response options, Reverse-scored items, Filler items, Subscales / structure and Total scoring; and from the Master Item List, all Item Text rows for that code in item number order.
A4: Prompt
A5: I want to convert this form to a different psychometric assessment. Keep the existing layout, branding and client details section exactly as they are, and make the following changes. 1. Title Change the form title to name the construct being measured, for example "Thinking Patterns Assessment". Use the plain construct name rather than instrument acronyms. 2. Introduction Keep the introductory paragraph, but rewrite its closing sentence so it explains why this assessment is being used and what it will help us understand. Keep the tone warm and plain, avoid clinical or diagnostic language, and write in UK English. 3. Client details Keep this section, its fields and its position unchanged. 4. Psychometric pages Delete the existing psychometric questions and replace them with the instruments below, one page per instrument. On each page: - Use the instrument's full name as the page heading. - Add the respondent instructions exactly as given. - Add every item exactly as worded and in the order given. Do not paraphrase, shorten or correct any item, including American spelling. - Number the items and make every item required. - Use the same question type for every item within an instrument. 5. Response scales Use the response scale given for each instrument, with the exact anchor labels and numeric values. Check that the scale fits the wording of the instructions (for example, a "how often" instruction needs a frequency scale, and a "how true" instruction needs an agreement or truth scale). Directly under the instructions on each page, add one sentence explaining how to use the scale and naming its anchors, for example: "Choose 1 if the statement is not at all true of you, through to 5 if it is completely true." 6. Scoring Add calculated fields that score each instrument according to the scoring information below. - Reverse score the listed items before adding them up. A reversed score is (scale maximum plus scale minimum) minus the response. - Record filler items but leave them out of every score. - Create one calculated field per subscale, plus a total only where the scoring information says a total is used. Where it says subscales are kept separate, do not create a total. - Name each calculated field with the instrument code and subscale, for example PTQ_Total or RRS_Brooding. - Keep every calculated field hidden from the respondent, so that no scores appear on the form or the thank you page. 7. Check back When you have finished, list back to me each page heading, the number of items per instrument, the response scale used, the reverse scored items, and each calculated field with its formula, so that I can check them against my codebook. Psychometric information: [Paste the codebook rows for each instrument here: name and code, instructions, response options, items, reverse scored items, filler items, subscales with item numbers, and total scoring.]
A7: Checks after Tally has built the form
A8: Item count on each page matches the Items in instrument column of the Instrument Summary.
A9: Item wording matches the Master Item List exactly, including spelling.
A10: Reverse scored items are reversed in the calculated fields, and filler items are excluded.
A11: The BPNSFS and RRS have subscale fields only, with no combined total.
A12: Calculated fields are hidden, so no scores appear on the form or the thank you page.
A13: Submit a test response and check each calculated field by hand against the scoring rules before sending the form to a client.

Sheet Instrument Summary
A1: Code | B1: Instrument Name | C1: Domain | D1: Availability | E1: Items in instrument | F1: Items in this codebook | G1: Construct measured | H1: Respondent | I1: Age range | J1: Administration time | K1: Cost and access | L1: Coaching application | M1: Purpose | N1: Instructions / prompt | O1: Response options | P1: Reverse-scored items | Q1: Filler items (not scored) | R1: Subscales / structure | S1: Total scoring | T1: Interpretation bands | U1: Cut-offs | V1: Normative data | W1: Psychometric properties | X1: Developer citation | Y1: Copyright and licensing | Z1: Source URL
A2: ESQ-R | B2: Executive Skills Questionnaire - Revised (ESQ-R) | C2: 1. Executive functioning and ADHD | D2: Free / open access | E2: 25 | F2: =COUNTIF('Master Item List'!$A:$A,$A2) | G2: Executive functioning skills, including plan and time management, organization, and emotional and behavioral regulation | H2: Self-report | I2: 14+ | J2: 5 minutes | K2: Included on NovoPsych with the permission of Dr Peg Dawson; blank form hosted free. Scoring and percentiles need a NovoPsych account. | L2: The core executive skills profile for coaching; the five subscales map directly onto coaching targets. Measures higher order skills rather than core executive functions. | M2: The ESQ-R is a 25-item self-report measure of executive functioning skills, including plan and time management, organization, and emotional and behavioral regulation. It was developed and published by Strait et al. (2020) and is included on NovoPsych with permission from Dr. Peg Dawson. It is intended to help identify specific areas of executive skill difficulty across five domains. | N2: Read each item and decide how often it's a problem for you. | O2: Never or rarely = 0 | Sometimes = 1 | Often = 2 | Very often = 3 | P2: None | Q2: None | R2: Plan Management (items 6-7, 12-14, 16-18, 22-24; n=11; range 0-33) Time Management (items 10-11, 15, 20; n=4; range 0-12) Organization (items 3, 8-9; n=3; range 0-9) Emotional Regulation (items 4-5, 21; n=3; range 0-9) Behavioral Regulation (items 1-2, 19, 25; n=4; range 0-12) | S2: Each item is rated on a 4-point Likert-type scale from 0 to 3 reflecting the frequency with which a respondent experiences a specific difficulty. Item scores are summed to produce a total score (range 0-75) and five subscale scores (Plan Management 0-33, Time Management 0-12, Organization 0-9, Emotional Regulation 0-9, Behavioral Regulation 0-12). Higher scores indicate more difficulties with executive functioning. No reverse-scored items were identified in the retrieved source material. | T2: Low Difficulties: ≤10th percentile - Low difficulties with executive functioning skills relative to the normative sample. Below Average Difficulties: 10th-24th percentile - Below average difficulties with executive functioning skills relative to the normative sample. Average Difficulties: 25th-75th percentile - Average difficulties with executive functioning skills relative to the normative sample. Above Average Difficulties: 76th-89th percentile - Above average difficulties with executive functioning skills relative to the normative sample. High Difficulties: ≥90th percentile - High difficulties with executive functioning skills relative to the normative sample. | U2: No diagnostic cut-off. Total score percentile bands: Low Difficulties (<=10th), Below Average (11th-24th), Average (25th-75th), Above Average (76th-89th), High (>=90th). Above Average or High suggests clinically significant executive functioning challenges. Subscale average ratings: No or Low Difficulty 0-1; Moderate Difficulty 1.01-1.99; High Difficulty 2-3. A change of 5 or more points on the total score is a Minimally Important Difference. | V2: Sample of 327 working adults in Malaysia (153 male, 171 female, 1 unknown; aged 23-80, M = 40.34, SD = 10.39) completing a modified ESQ-R (Nasir et al., 2021). Total M = 20.54 (SD 10.27); Plan Management M = 7.59 (SD 5.08); Time Management M = 3.03 (SD 2.24); Organization M = 2.57 (SD 1.96); Emotional Regulation M = 3.02 (SD 1.88); Behavioral Regulation M = 4.32 (SD 2.08). These means and SDs convert raw scores to percentiles. | W2: Internal consistency Cronbach's alpha = .91; test-retest reliability r = .70 (Strait et al., 2020). Factor alphas: Plan Management .89 (11 items), Time Management .74 (4), Organization .76 (3), Emotional Regulation .75 (3), Behavioral Regulation .65 (4). Convergent validity: Current Behavior Scale r = .74; Adult Executive Functioning Inventory r = .69. Discriminant validity: DASS-21 Depression r = .48, Anxiety r = .38, Stress r = .44; GAD-7 r = .45; PSS-10 r = .55. Academic engagement r = -.40. | X2: Developed by Dr. Peg Dawson (Smart But Scattered Kids). Original citation: Strait, J. E., Dawson, P., Walther, C. A. P., Strait, G. G., Barton, A. K., & McClain, M. B. (2020). Refinement and psychometric evaluation of the Executive Skills Questionnaire-Revised. Contemporary School Psychology, 24, 378-388. https://doi.org/10.1007/s40688-018-00224-x | Y2: © 2026 Copyright – NovoPsych – All rights reserved. The ESQ-R was developed and published by Strait et al. (2020) and is included on NovoPsych with permission from Dr. Peg Dawson. | Z2: https://novopsych.com/assessments/formulation/executive-skills-questionnaire-revised-esq-r/
A3: CFI | B3: Cognitive Flexibility Inventory (CFI) | C3: 1. Executive functioning and ADHD | D3: Free / open access | E3: 20 | F3: =COUNTIF('Master Item List'!$A:$A,$A3) | G3: Cognitive flexibility - the ability to perceive multiple alternative explanations for life occurrences and human behaviour, generate multiple alternative solutions to difficult situations, and perceive difficult situations as controllable | H3: Self-report | I3: 18+ | J3: 3 minutes | K3: Published in Dennis and Vander Wal (2010); blank form hosted free on NovoPsych. | L3: Measures cognitive flexibility, useful for tracking response to reframing and problem solving work. Scored in the opposite direction to the ESQ-R. | M3: The CFI is a 20-item self-report measure used to monitor how often individuals engaged in cognitive behavioural thought challenging interventions. Cognitive flexibility is a core skill targeted in cognitive behavioral therapy that enables adaptive thinking during stressful life events and helps individuals avoid maladaptive thinking patterns. | N3: Please use the scale below to indicate the extent to which you agree or disagree with the following statements. | O3: Strongly disagree = 1 | Disagree = 2 | Somewhat disagree = 3 | Neutral = 4 | Somewhat agree = 5 | Agree = 6 | Strongly agree = 7 | P3: 2, 4, 7, 9, 11, 17 | Q3: None | R3: Alternatives (items 1, 3, 5-6, 8, 10, 12-14, 16, 18-20; n=13; range 13-91) Control (items 2, 4, 7, 9, 11, 15, 17; n=7; range 7-49) | S3: Each item is rated on a 7-point Likert scale from 1 (Strongly disagree) to 7 (Strongly agree). Items 2, 4, 7, 9, 11, and 17 are reverse scored. Item scores are summed to produce a total CFI score and two subscale scores (Alternatives and Control). A higher score indicates more cognitive flexibility. | T3: Clinically significant inflexibility: Below approximately the 25th percentile - Cognitive inflexibility of clinical significance; a target for CBT. Average: Around the 50th percentile - More cognitive flexibility than 50 per cent of the normative sample. High flexibility: Upper percentiles - Higher likelihood of adaptive responses to difficult life experiences. | U3: No formal diagnostic cut-off. Percentiles below approximately 25 represent clinically significant cognitive inflexibility, which would be important to target within cognitive behavioural therapy. | V3: Sample of 196 university students (Dennis & Vander Wal, 2010): CFI total M = 102.98 (SD = 13.91); Alternatives M = 67.59 (SD = 9.41); Control M = 35.35 (SD = 7.02). | W3: Test-retest reliability: total r = .81; Alternatives r = .75; Control r = .77 (Dennis & Vander Wal, 2010). Internal consistency: Alternatives alpha = .91; Control alpha = .86; total alpha = .90. Convergent construct validity established through associations with other measures of cognitive flexibility, depressive symptomatology and coping (Dennis & Vander Wal, 2010). The CFI differentiates a clinical group (anxiety and depression) from a non-clinical sample, with the clinical group scoring significantly lower on total and subscale scores (Johnco, Wuthrich, & Rapee, 2014). | X3: Dennis, J. P., & Vander Wal, J. S. (2010). The cognitive flexibility inventory: Instrument development and estimates of reliability and validity. Cognitive Therapy and Research, 34(3), 241-253. https://doi.org/10.1007/s10608-009-9276-4 | Y3: © 2026 Copyright – NovoPsych – All rights reserved. Sample report footer: Copyright 2022 NovoPsych Pty Ltd. | Z3: https://novopsych.com/assessments/formulation/cognitive-flexibility-inventory-cfi/
A4: ASRS | B4: Adult ADHD Self-Report Scale (ASRS v1.1) | C4: 1. Executive functioning and ADHD | D4: Free / open access | E4: 18 | F4: =COUNTIF('Master Item List'!$A:$A,$A4) | G4: Attention Deficit Hyperactivity Disorder (ADHD) symptoms in adults, spanning inattentiveness and hyperactivity/impulsivity (including motor and verbal components) | H4: self-report | I4: 18+ | J4: 3 minutes | K4: Public domain WHO instrument. Blank form hosted free on NovoPsych; scoring and reports need a NovoPsych account. | L4: Screening and severity measure for current adult ADHD symptoms; pairs with the WURS-25 for childhood history. Not a diagnostic instrument on its own. | M4: The ASRS v1.1 is an 18-item self-report questionnaire designed to assess ADHD symptoms in adults. It is based on the World Health Organization Composite International Diagnostic Interview (2001) and is worded to be consistent with both DSM-IV and DSM-5-TR criteria as they manifest in adults. It is intended as a screening tool used alongside clinical interview and other measures (e.g. the WURS for childhood history) rather than as a standalone diagnostic instrument. | N4: Please answer the questions below, rating yourself on each of the criteria shown. As you answer each question, select the box that best describes how you have felt and conducted yourself over the past 6 months. | O4: Never = 0 | Rarely = 1 | Sometimes = 2 | Often = 3 | Very Often = 4 | P4: None | Q4: None | R4: Part A (Criterion / Screener) (items 1-6; n=6; range 0-24) Part B (Additional Symptoms) (items 7-18; n=12; range 0-48) Inattentiveness (items 1-4, 7-11; n=9; range 0-9 (dichotomous symptom count)) Hyperactivity/Impulsivity - Motor (items 5-6, 12-14; n=5; range 0-5 (dichotomous symptom count)) Hyperactivity/Impulsivity - Verbal (items 15-18; n=4; range 0-4 (dichotomous symptom count)) | S4: As of the 2024 update, each of the 18 items is scored on a 5-point Likert scale (Never=0, Rarely=1, Sometimes=2, Often=3, Very Often=4). Part A = sum of items 1-6 (range 0-24). Part B = sum of items 7-18 (range 0-48). Total = sum of all 18 items (range 0-72). The original dichotomous (0/1) scoring is still used separately to calculate the 'percent of symptoms endorsed' for subtype/subscale reporting. | T4: Part A - Low: 0-9 - Not consistent with an ADHD diagnosis. Part A - Mild to Moderate: 10-13 - Below the screening threshold; some symptoms reported. Part A - High: 14-17 - Clinically significant. Symptom profile consistent with a DSM-5-TR ADHD diagnosis in adults. Part A - Very High: 18-24 - Clinically significant; symptoms endorsed at high frequency. Part B - Low: 0-19 - Low additional symptom burden. Part B - Mild to Moderate: 20-26 - Below the clinically significant range. Part B - High: 27-32 - Clinically significant. Part B - Very High: 33-48 - Clinically significant; high additional symptom burden. Total - Low: 0-30 - Low overall symptom burden. Total - Mild to Moderate: 31-39 - Below the range typical of adults with ADHD. Total - High: 40-49 - At or above the 79th percentile; in most cases someone with ADHD will score in this range or above. Total - Very High: 50-72 - Very high overall symptom burden. | U4: Part A >= 14 constitutes a positive screen and a symptom profile consistent with a DSM-5-TR adult ADHD diagnosis (Adler et al., 2006; Kessler et al., 2007; Harvard Medical School, 2024). Part B >= 27 is clinically significant. A total score at or above the 79th percentile (raw >= 40) typically indicates ADHD. Kessler et al. (2007) four-level Part A classification: 0-9, 10-13, 14-17, 18-24 (AUC = 0.90). Always use alongside clinical interview. | V4: Adler et al. (2018/2019) sample of 22,397 adults, 465 (2.1%) self-reporting a physician ADHD diagnosis. NovoPsych recalculated summed means/SDs (Likert scoring), accounting for inter-item correlations (r = 0.32 within parts, r = 0.74 between Parts A and B). ADHD group (n = 465): Part A M = 16.71 (SD 5.07); Part B M = 32.74 (SD 9.16); Total M = 49.45 (SD 13.36). Community sample (n = 21,932): Part A M = 10.88 (SD 3.76); Part B M = 21.60 (SD 6.69); Total M = 32.48 (SD 9.80). | W4: Internal consistency: Cronbach's alpha = .88 in adult ADHD patients (Adler et al., 2006); .952 for the full scale (Brevik et al., 2020). Concurrent validity with clinician-rated symptoms r = .84 (Adler et al., 2006). Diagnostic accuracy: AUC = .904 for the 18-item scale and .903 for the six Part A items (Brevik et al., 2020); AUC = .90 for the Kessler et al. (2007) four-level Part A classification. Under the previous scoring convention, sensitivity 1.0, specificity .71, PPP .52, NPP 1.0 (Hines, King & Curry, 2012). Combined with the WURS-25, AUC = .964. Factor structure: CFA in over 1,000 adults identified three factors - Inattentiveness, Motor Hyperactivity/Impulsivity, Verbal Hyperactivity/Impulsivity (Stanton et al., 2018). | X4: Kessler, R. C., Adler, L., Ames, M., Demler, O., Faraone, S., Hiripi, E., Howes, M. J., Jin, R., Secnik, K., Spencer, T., Ustun, T. B., & Walters, E. E. (2005). The World Health Organization Adult ADHD Self-Report Scale (ASRS): a short screening scale for use in the general population. Psychological Medicine, 35(2), 245-256. https://doi.org/10.1017/s0033291704002892 | Y4: Public-domain WHO instrument (ASRS v1.1 Symptom Checklist). Freely reproducible for clinical and research use; NovoPsych hosts the blank form as a public PDF. | Z4: https://novopsych.com/assessments/diagnosis/adult-adhd-self-report-scale-asrs/
